[2022-08-03 00:50:02,069] {taskinstance.py:826} INFO - Dependencies all met for <TaskInstance: penjadwalan.dapat_suhu 2022-08-03T00:48:00+00:00 [queued]>
[2022-08-03 00:50:02,125] {taskinstance.py:826} INFO - Dependencies all met for <TaskInstance: penjadwalan.dapat_suhu 2022-08-03T00:48:00+00:00 [queued]>
[2022-08-03 00:50:02,126] {taskinstance.py:1017} INFO - 
--------------------------------------------------------------------------------
[2022-08-03 00:50:02,126] {taskinstance.py:1018} INFO - Starting attempt 1 of 1
[2022-08-03 00:50:02,127] {taskinstance.py:1019} INFO - 
--------------------------------------------------------------------------------
[2022-08-03 00:50:02,175] {taskinstance.py:1038} INFO - Executing <Task(PythonOperator): dapat_suhu> on 2022-08-03T00:48:00+00:00
[2022-08-03 00:50:02,180] {standard_task_runner.py:51} INFO - Started process 6450 to run task
[2022-08-03 00:50:02,186] {standard_task_runner.py:75} INFO - Running: ['airflow', 'tasks', 'run', 'penjadwalan', 'dapat_suhu', '2022-08-03T00:48:00+00:00', '--job-id', '431', '--pool', 'default_pool', '--raw', '--subdir', 'DAGS_FOLDER/penjadwalan.py', '--cfg-path', '/tmp/tmpfb0y9fwn']
[2022-08-03 00:50:02,199] {standard_task_runner.py:76} INFO - Job 431: Subtask dapat_suhu
[2022-08-03 00:50:02,367] {logging_mixin.py:103} INFO - Running <TaskInstance: penjadwalan.dapat_suhu 2022-08-03T00:48:00+00:00 [running]> on host b4dcda255553
[2022-08-03 00:50:02,546] {taskinstance.py:1232} INFO - Exporting the following env vars:
AIRFLOW_CTX_DAG_OWNER=airflow
AIRFLOW_CTX_DAG_ID=penjadwalan
AIRFLOW_CTX_TASK_ID=dapat_suhu
AIRFLOW_CTX_EXECUTION_DATE=2022-08-03T00:48:00+00:00
AIRFLOW_CTX_DAG_RUN_ID=scheduled__2022-08-03T00:48:00+00:00
[2022-08-03 00:50:15,090] {taskinstance.py:1396} ERROR - ('Connection aborted.', RemoteDisconnected('Remote end closed connection without response',))
Traceback (most recent call last):
  File "/home/airflow/.local/lib/python3.6/site-packages/urllib3/connectionpool.py", line 677, in urlopen
    chunked=chunked,
  File "/home/airflow/.local/lib/python3.6/site-packages/urllib3/connectionpool.py", line 426, in _make_request
    six.raise_from(e, None)
  File "<string>", line 3, in raise_from
  File "/home/airflow/.local/lib/python3.6/site-packages/urllib3/connectionpool.py", line 421, in _make_request
    httplib_response = conn.getresponse()
  File "/usr/local/lib/python3.6/http/client.py", line 1383, in getresponse
    response.begin()
  File "/usr/local/lib/python3.6/http/client.py", line 320, in begin
    version, status, reason = self._read_status()
  File "/usr/local/lib/python3.6/http/client.py", line 289, in _read_status
    raise RemoteDisconnected("Remote end closed connection without"
http.client.RemoteDisconnected: Remote end closed connection without response

During handling of the above exception, another exception occurred:

Traceback (most recent call last):
  File "/home/airflow/.local/lib/python3.6/site-packages/requests/adapters.py", line 449, in send
    timeout=timeout
  File "/home/airflow/.local/lib/python3.6/site-packages/urllib3/connectionpool.py", line 727, in urlopen
    method, url, error=e, _pool=self, _stacktrace=sys.exc_info()[2]
  File "/home/airflow/.local/lib/python3.6/site-packages/urllib3/util/retry.py", line 410, in increment
    raise six.reraise(type(error), error, _stacktrace)
  File "/home/airflow/.local/lib/python3.6/site-packages/urllib3/packages/six.py", line 734, in reraise
    raise value.with_traceback(tb)
  File "/home/airflow/.local/lib/python3.6/site-packages/urllib3/connectionpool.py", line 677, in urlopen
    chunked=chunked,
  File "/home/airflow/.local/lib/python3.6/site-packages/urllib3/connectionpool.py", line 426, in _make_request
    six.raise_from(e, None)
  File "<string>", line 3, in raise_from
  File "/home/airflow/.local/lib/python3.6/site-packages/urllib3/connectionpool.py", line 421, in _make_request
    httplib_response = conn.getresponse()
  File "/usr/local/lib/python3.6/http/client.py", line 1383, in getresponse
    response.begin()
  File "/usr/local/lib/python3.6/http/client.py", line 320, in begin
    version, status, reason = self._read_status()
  File "/usr/local/lib/python3.6/http/client.py", line 289, in _read_status
    raise RemoteDisconnected("Remote end closed connection without"
urllib3.exceptions.ProtocolError: ('Connection aborted.', RemoteDisconnected('Remote end closed connection without response',))

During handling of the above exception, another exception occurred:

Traceback (most recent call last):
  File "/home/airflow/.local/lib/python3.6/site-packages/airflow/models/taskinstance.py", line 1086, in _run_raw_task
    self._prepare_and_execute_task_with_callbacks(context, task)
  File "/home/airflow/.local/lib/python3.6/site-packages/airflow/models/taskinstance.py", line 1260, in _prepare_and_execute_task_with_callbacks
    result = self._execute_task(context, task_copy)
  File "/home/airflow/.local/lib/python3.6/site-packages/airflow/models/taskinstance.py", line 1300, in _execute_task
    result = task_copy.execute(context=context)
  File "/home/airflow/.local/lib/python3.6/site-packages/airflow/operators/python.py", line 117, in execute
    return_value = self.execute_callable()
  File "/home/airflow/.local/lib/python3.6/site-packages/airflow/operators/python.py", line 128, in execute_callable
    return self.python_callable(*self.op_args, **self.op_kwargs)
  File "/opt/airflow/dags/penjadwalan.py", line 30, in panggilsuhu
    print(getdata(kota))
  File "/opt/airflow/dags/penjadwalan.py", line 9, in getdata
    hasil = requests.post("https://api.openweathermap.org/data/2.5/weather?q="+namakota+"&appid=d5f11f21e3d4617bc66950d463fdeb4b")
  File "/home/airflow/.local/lib/python3.6/site-packages/requests/api.py", line 119, in post
    return request('post', url, data=data, json=json, **kwargs)
  File "/home/airflow/.local/lib/python3.6/site-packages/requests/api.py", line 61, in request
    return session.request(method=method, url=url, **kwargs)
  File "/home/airflow/.local/lib/python3.6/site-packages/requests/sessions.py", line 530, in request
    resp = self.send(prep, **send_kwargs)
  File "/home/airflow/.local/lib/python3.6/site-packages/requests/sessions.py", line 643, in send
    r = adapter.send(request, **kwargs)
  File "/home/airflow/.local/lib/python3.6/site-packages/requests/adapters.py", line 498, in send
    raise ConnectionError(err, request=request)
requests.exceptions.ConnectionError: ('Connection aborted.', RemoteDisconnected('Remote end closed connection without response',))
[2022-08-03 00:50:15,103] {taskinstance.py:1440} INFO - Marking task as FAILED. dag_id=penjadwalan, task_id=dapat_suhu, execution_date=20220803T004800, start_date=20220803T005002, end_date=20220803T005015
[2022-08-03 00:50:15,162] {local_task_job.py:118} INFO - Task exited with return code 1
