[2022-08-03 00:46:47,936] {taskinstance.py:826} INFO - Dependencies all met for <TaskInstance: penjadwalan.dapat_suhu 2022-08-02T22:08:00+00:00 [queued]>
[2022-08-03 00:46:47,965] {taskinstance.py:826} INFO - Dependencies all met for <TaskInstance: penjadwalan.dapat_suhu 2022-08-02T22:08:00+00:00 [queued]>
[2022-08-03 00:46:47,966] {taskinstance.py:1017} INFO - 
--------------------------------------------------------------------------------
[2022-08-03 00:46:47,966] {taskinstance.py:1018} INFO - Starting attempt 1 of 1
[2022-08-03 00:46:47,967] {taskinstance.py:1019} INFO - 
--------------------------------------------------------------------------------
[2022-08-03 00:46:47,982] {taskinstance.py:1038} INFO - Executing <Task(PythonOperator): dapat_suhu> on 2022-08-02T22:08:00+00:00
[2022-08-03 00:46:47,988] {standard_task_runner.py:51} INFO - Started process 29476 to run task
[2022-08-03 00:46:48,000] {standard_task_runner.py:75} INFO - Running: ['airflow', 'tasks', 'run', 'penjadwalan', 'dapat_suhu', '2022-08-02T22:08:00+00:00', '--job-id', '351', '--pool', 'default_pool', '--raw', '--subdir', 'DAGS_FOLDER/penjadwalan.py', '--cfg-path', '/tmp/tmpbb9ezjk4']
[2022-08-03 00:46:48,004] {standard_task_runner.py:76} INFO - Job 351: Subtask dapat_suhu
[2022-08-03 00:46:48,088] {logging_mixin.py:103} INFO - Running <TaskInstance: penjadwalan.dapat_suhu 2022-08-02T22:08:00+00:00 [running]> on host b4dcda255553
[2022-08-03 00:46:48,167] {taskinstance.py:1232} INFO - Exporting the following env vars:
AIRFLOW_CTX_DAG_OWNER=airflow
AIRFLOW_CTX_DAG_ID=penjadwalan
AIRFLOW_CTX_TASK_ID=dapat_suhu
AIRFLOW_CTX_EXECUTION_DATE=2022-08-02T22:08:00+00:00
AIRFLOW_CTX_DAG_RUN_ID=scheduled__2022-08-02T22:08:00+00:00
[2022-08-03 00:46:51,851] {taskinstance.py:1396} ERROR - HTTPSConnectionPool(host='api.openweathermap.org', port=443): Max retries exceeded with url: /data/2.5/weather?q=Bali&appid=d5f11f21e3d4617bc66950d463fdeb4b (Caused by SSLError(SSLError("bad handshake: SysCallError(-1, 'Unexpected EOF')",),))
Traceback (most recent call last):
  File "/home/airflow/.local/lib/python3.6/site-packages/urllib3/contrib/pyopenssl.py", line 488, in wrap_socket
    cnx.do_handshake()
  File "/home/airflow/.local/lib/python3.6/site-packages/OpenSSL/SSL.py", line 1934, in do_handshake
    self._raise_ssl_error(self._ssl, result)
  File "/home/airflow/.local/lib/python3.6/site-packages/OpenSSL/SSL.py", line 1664, in _raise_ssl_error
    raise SysCallError(-1, "Unexpected EOF")
OpenSSL.SSL.SysCallError: (-1, 'Unexpected EOF')

During handling of the above exception, another exception occurred:

Traceback (most recent call last):
  File "/home/airflow/.local/lib/python3.6/site-packages/urllib3/connectionpool.py", line 677, in urlopen
    chunked=chunked,
  File "/home/airflow/.local/lib/python3.6/site-packages/urllib3/connectionpool.py", line 381, in _make_request
    self._validate_conn(conn)
  File "/home/airflow/.local/lib/python3.6/site-packages/urllib3/connectionpool.py", line 978, in _validate_conn
    conn.connect()
  File "/home/airflow/.local/lib/python3.6/site-packages/urllib3/connection.py", line 371, in connect
    ssl_context=context,
  File "/home/airflow/.local/lib/python3.6/site-packages/urllib3/util/ssl_.py", line 386, in ssl_wrap_socket
    return context.wrap_socket(sock, server_hostname=server_hostname)
  File "/home/airflow/.local/lib/python3.6/site-packages/urllib3/contrib/pyopenssl.py", line 494, in wrap_socket
    raise ssl.SSLError("bad handshake: %r" % e)
ssl.SSLError: ("bad handshake: SysCallError(-1, 'Unexpected EOF')",)

During handling of the above exception, another exception occurred:

Traceback (most recent call last):
  File "/home/airflow/.local/lib/python3.6/site-packages/requests/adapters.py", line 449, in send
    timeout=timeout
  File "/home/airflow/.local/lib/python3.6/site-packages/urllib3/connectionpool.py", line 727, in urlopen
    method, url, error=e, _pool=self, _stacktrace=sys.exc_info()[2]
  File "/home/airflow/.local/lib/python3.6/site-packages/urllib3/util/retry.py", line 446, in increment
    raise MaxRetryError(_pool, url, error or ResponseError(cause))
urllib3.exceptions.MaxRetryError: HTTPSConnectionPool(host='api.openweathermap.org', port=443): Max retries exceeded with url: /data/2.5/weather?q=Bali&appid=d5f11f21e3d4617bc66950d463fdeb4b (Caused by SSLError(SSLError("bad handshake: SysCallError(-1, 'Unexpected EOF')",),))

During handling of the above exception, another exception occurred:

Traceback (most recent call last):
  File "/home/airflow/.local/lib/python3.6/site-packages/airflow/models/taskinstance.py", line 1086, in _run_raw_task
    self._prepare_and_execute_task_with_callbacks(context, task)
  File "/home/airflow/.local/lib/python3.6/site-packages/airflow/models/taskinstance.py", line 1260, in _prepare_and_execute_task_with_callbacks
    result = self._execute_task(context, task_copy)
  File "/home/airflow/.local/lib/python3.6/site-packages/airflow/models/taskinstance.py", line 1300, in _execute_task
    result = task_copy.execute(context=context)
  File "/home/airflow/.local/lib/python3.6/site-packages/airflow/operators/python.py", line 117, in execute
    return_value = self.execute_callable()
  File "/home/airflow/.local/lib/python3.6/site-packages/airflow/operators/python.py", line 128, in execute_callable
    return self.python_callable(*self.op_args, **self.op_kwargs)
  File "/opt/airflow/dags/penjadwalan.py", line 30, in panggilsuhu
    print(getdata(kota))
  File "/opt/airflow/dags/penjadwalan.py", line 9, in getdata
    hasil = requests.post("https://api.openweathermap.org/data/2.5/weather?q="+namakota+"&appid=d5f11f21e3d4617bc66950d463fdeb4b")
  File "/home/airflow/.local/lib/python3.6/site-packages/requests/api.py", line 119, in post
    return request('post', url, data=data, json=json, **kwargs)
  File "/home/airflow/.local/lib/python3.6/site-packages/requests/api.py", line 61, in request
    return session.request(method=method, url=url, **kwargs)
  File "/home/airflow/.local/lib/python3.6/site-packages/requests/sessions.py", line 530, in request
    resp = self.send(prep, **send_kwargs)
  File "/home/airflow/.local/lib/python3.6/site-packages/requests/sessions.py", line 643, in send
    r = adapter.send(request, **kwargs)
  File "/home/airflow/.local/lib/python3.6/site-packages/requests/adapters.py", line 514, in send
    raise SSLError(e, request=request)
requests.exceptions.SSLError: HTTPSConnectionPool(host='api.openweathermap.org', port=443): Max retries exceeded with url: /data/2.5/weather?q=Bali&appid=d5f11f21e3d4617bc66950d463fdeb4b (Caused by SSLError(SSLError("bad handshake: SysCallError(-1, 'Unexpected EOF')",),))
[2022-08-03 00:46:51,889] {taskinstance.py:1440} INFO - Marking task as FAILED. dag_id=penjadwalan, task_id=dapat_suhu, execution_date=20220802T220800, start_date=20220803T004647, end_date=20220803T004651
[2022-08-03 00:46:51,946] {local_task_job.py:118} INFO - Task exited with return code 1
